Workbook

Sheet Dashboard
A1: RINGKASAN & PRIORITAS PROYEK TIM
A2: =" Diperbarui otomatis per: "&TEXT(TODAY(),"DD MMMM YYYY")&" | Seluruh angka menarik data dari sheet Data Proyek." -> Diperbarui otomatis per: 28 August 2026 | Seluruh angka menarik data dari sheet Data Proyek.
A4: Total Proyek | B4: Prioritas KRITIS | C4: Total Nilai (Rp) | D4: Proyek Berjalan | E4: =Referensi!$A$5 -> Enterprise JSI | F4: =Referensi!$A$6 -> Consultant | G4: Perlu Follow Up | H4: Deadline Terlewat
A5: =COUNTIF('Data Proyek'!$C$5:$C$204,"?*") -> 17 | B5: =COUNTIF('Data Proyek'!$T$5:$T$204,"KRITIS") -> 0 | C5: =SUM('Data Proyek'!$U$5:$U$204) -> 11503854400 | D5: =COUNTIF('Data Proyek'!$L$5:$L$204,"Berjalan") -> 3 | E5: =COUNTIF('Data Proyek'!$I$5:$I$204,Referensi!$A$5) -> 17 | F5: =COUNTIF('Data Proyek'!$I$5:$I$204,Referensi!$A$6) -> 0 | G5: =COUNTIF('Data Proyek'!$R$5:$R$204,"Segera follow up") -> 0 | H5: =COUNTIF('Data Proyek'!$Q$5:$Q$204,"<0") -> 0
A7: DAFTAR PRIORITAS UTAMA — 10 PROYEK DENGAN SKOR TERTINGGI
A8: Nama Proyek | B8: Kode Proyek | C8: Klien / Instansi | D8: PIC | E8: Level Prioritas | F8: Status | G8: Skor | H8: Sisa Hari
A9: {=IF($I9="","",INDEX('Data Proyek'!$C$5:$C$204,MATCH($I9,'Data Proyek'!$W$5:$W$204,0)))} -> X500 CHCNAV, AA6 | B9: {=IF($I9="","",INDEX('Data Proyek'!$B$5:$B$204,MATCH($I9,'Data Proyek'!$W$5:$W$204,0)))} -> JSI-ENT-PNJ-002 | C9: {=IF($I9="","",INDEX('Data Proyek'!$D$5:$D$204,MATCH($I9,'Data Proyek'!$W$5:$W$204,0)))} -> Dinas Perumahan Rakyat, Kab HST | D9: {=IF($I9="","",INDEX('Data Proyek'!$K$5:$K$204,MATCH($I9,'Data Proyek'!$W$5:$W$204,0)))} -> Rika | E9: {=IF($I9="","",INDEX('Data Proyek'!$T$5:$T$204,MATCH($I9,'Data Proyek'!$W$5:$W$204,0)))} -> Tinggi | F9: {=IF($I9="","",INDEX('Data Proyek'!$L$5:$L$204,MATCH($I9,'Data Proyek'!$W$5:$W$204,0)))} -> Penawaran | G9: =IF($I9="","",INT($I9)) -> 62 | H9: {=IF($I9="","",INDEX('Data Proyek'!$Q$5:$Q$204,MATCH($I9,'Data Proyek'!$W$5:$W$204,0)))} | I9: =IFERROR(LARGE('Data Proyek'!$W$5:$W$204,1),"") -> 62.00021
A10: {=IF($I10="","",INDEX('Data Proyek'!$C$5:$C$204,MATCH($I10,'Data Proyek'!$W$5:$W$204,0)))} -> P60 CHCNAV, AA15 | B10: {=IF($I10="","",INDEX('Data Proyek'!$B$5:$B$204,MATCH($I10,'Data Proyek'!$W$5:$W$204,0)))} -> JSI-ENT-PNJ-001 | C10: {=IF($I10="","",INDEX('Data Proyek'!$D$5:$D$204,MATCH($I10,'Data Proyek'!$W$5:$W$204,0)))} -> PT Bintang Delapan Mineral | D10: {=IF($I10="","",INDEX('Data Proyek'!$K$5:$K$204,MATCH($I10,'Data Proyek'!$W$5:$W$204,0)))} -> Rika | E10: {=IF($I10="","",INDEX('Data Proyek'!$T$5:$T$204,MATCH($I10,'Data Proyek'!$W$5:$W$204,0)))} -> Tinggi | F10: {=IF($I10="","",INDEX('Data Proyek'!$L$5:$L$204,MATCH($I10,'Data Proyek'!$W$5:$W$204,0)))} -> Negosiasi | G10: =IF($I10="","",INT($I10)) -> 62 | H10: {=IF($I10="","",INDEX('Data Proyek'!$Q$5:$Q$204,MATCH($I10,'Data Proyek'!$W$5:$W$204,0)))} | I10: =IFERROR(LARGE('Data Proyek'!$W$5:$W$204,2),"") -> 62.0002
A11: {=IF($I11="","",INDEX('Data Proyek'!$C$5:$C$204,MATCH($I11,'Data Proyek'!$W$5:$W$204,0)))} -> Topografi Foto Udara | B11: {=IF($I11="","",INDEX('Data Proyek'!$B$5:$B$204,MATCH($I11,'Data Proyek'!$W$5:$W$204,0)))} -> JSI-ENT-JAS-008 | C11: {=IF($I11="","",INDEX('Data Proyek'!$D$5:$D$204,MATCH($I11,'Data Proyek'!$W$5:$W$204,0)))} -> PT Trimata Coal Perkasa | D11: {=IF($I11="","",INDEX('Data Proyek'!$K$5:$K$204,MATCH($I11,'Data Proyek'!$W$5:$W$204,0)))} -> Rika | E11: {=IF($I11="","",INDEX('Data Proyek'!$T$5:$T$204,MATCH($I11,'Data Proyek'!$W$5:$W$204,0)))} -> Tinggi | F11: {=IF($I11="","",INDEX('Data Proyek'!$L$5:$L$204,MATCH($I11,'Data Proyek'!$W$5:$W$204,0)))} -> Negosiasi | G11: =IF($I11="","",INT($I11)) -> 62 | H11: {=IF($I11="","",INDEX('Data Proyek'!$Q$5:$Q$204,MATCH($I11,'Data Proyek'!$W$5:$W$204,0)))} | I11: =IFERROR(LARGE('Data Proyek'!$W$5:$W$204,3),"") -> 62.00014
A12: {=IF($I12="","",INDEX('Data Proyek'!$C$5:$C$204,MATCH($I12,'Data Proyek'!$W$5:$W$204,0)))} -> Topografi LiDAR 7000Ha | B12: {=IF($I12="","",INDEX('Data Proyek'!$B$5:$B$204,MATCH($I12,'Data Proyek'!$W$5:$W$204,0)))} -> JSI-ENT-JAS-007 | C12: {=IF($I12="","",INDEX('Data Proyek'!$D$5:$D$204,MATCH($I12,'Data Proyek'!$W$5:$W$204,0)))} -> PT Bhaktiputra Persada Nusantara | D12: {=IF($I12="","",INDEX('Data Proyek'!$K$5:$K$204,MATCH($I12,'Data Proyek'!$W$5:$W$204,0)))} -> Rika | E12: {=IF($I12="","",INDEX('Data Proyek'!$T$5:$T$204,MATCH($I12,'Data Proyek'!$W$5:$W$204,0)))} -> Tinggi | G12: =IF($I12="","",INT($I12)) -> 62 | H12: {=IF($I12="","",INDEX('Data Proyek'!$Q$5:$Q$204,MATCH($I12,'Data Proyek'!$W$5:$W$204,0)))} | I12: =IFERROR(LARGE('Data Proyek'!$W$5:$W$204,4),"") -> 62.00013
A13: {=IF($I13="","",INDEX('Data Proyek'!$C$5:$C$204,MATCH($I13,'Data Proyek'!$W$5:$W$204,0)))} -> Topografi LiDAR 4500 HA | B13: {=IF($I13="","",INDEX('Data Proyek'!$B$5:$B$204,MATCH($I13,'Data Proyek'!$W$5:$W$204,0)))} -> JSI-ENT-JAS-004 | C13: {=IF($I13="","",INDEX('Data Proyek'!$D$5:$D$204,MATCH($I13,'Data Proyek'!$W$5:$W$204,0)))} -> PT Sriwijaya Tansri Energi | D13: {=IF($I13="","",INDEX('Data Proyek'!$K$5:$K$204,MATCH($I13,'Data Proyek'!$W$5:$W$204,0)))} -> Nurdiyansah | E13: {=IF($I13="","",INDEX('Data Proyek'!$T$5:$T$204,MATCH($I13,'Data Proyek'!$W$5:$W$204,0)))} -> Tinggi | F13: {=IF($I13="","",INDEX('Data Proyek'!$L$5:$L$204,MATCH($I13,'Data Proyek'!$W$5:$W$204,0)))} -> Penawaran | G13: =IF($I13="","",INT($I13)) -> 62 | H13: {=IF($I13="","",INDEX('Data Proyek'!$Q$5:$Q$204,MATCH($I13,'Data Proyek'!$W$5:$W$204,0)))} | I13: =IFERROR(LARGE('Data Proyek'!$W$5:$W$204,5),"") -> 62.0001
A14: {=IF($I14="","",INDEX('Data Proyek'!$C$5:$C$204,MATCH($I14,'Data Proyek'!$W$5:$W$204,0)))} -> Topografi LiDAR 9000 HA | B14: {=IF($I14="","",INDEX('Data Proyek'!$B$5:$B$204,MATCH($I14,'Data Proyek'!$W$5:$W$204,0)))} -> JSI-ENT-JAS-003 | C14: {=IF($I14="","",INDEX('Data Proyek'!$D$5:$D$204,MATCH($I14,'Data Proyek'!$W$5:$W$204,0)))} -> PT Sriwijaya Tansri Energi | D14: {=IF($I14="","",INDEX('Data Proyek'!$K$5:$K$204,MATCH($I14,'Data Proyek'!$W$5:$W$204,0)))} -> Nurdiyansah | E14: {=IF($I14="","",INDEX('Data Proyek'!$T$5:$T$204,MATCH($I14,'Data Proyek'!$W$5:$W$204,0)))} -> Tinggi | F14: {=IF($I14="","",INDEX('Data Proyek'!$L$5:$L$204,MATCH($I14,'Data Proyek'!$W$5:$W$204,0)))} -> Penawaran | G14: =IF($I14="","",INT($I14)) -> 62 | H14: {=IF($I14="","",INDEX('Data Proyek'!$Q$5:$Q$204,MATCH($I14,'Data Proyek'!$W$5:$W$204,0)))} | I14: =IFERROR(LARGE('Data Proyek'!$W$5:$W$204,6),"") -> 62.00009
A15: {=IF($I15="","",INDEX('Data Proyek'!$C$5:$C$204,MATCH($I15,'Data Proyek'!$W$5:$W$204,0)))} -> Riset Carbon Stock | B15: {=IF($I15="","",INDEX('Data Proyek'!$B$5:$B$204,MATCH($I15,'Data Proyek'!$W$5:$W$204,0)))} -> JSI-ENT-RIS-001 | C15: {=IF($I15="","",INDEX('Data Proyek'!$D$5:$D$204,MATCH($I15,'Data Proyek'!$W$5:$W$204,0)))} -> Undip | D15: {=IF($I15="","",INDEX('Data Proyek'!$K$5:$K$204,MATCH($I15,'Data Proyek'!$W$5:$W$204,0)))} -> Harir | E15: {=IF($I15="","",INDEX('Data Proyek'!$T$5:$T$204,MATCH($I15,'Data Proyek'!$W$5:$W$204,0)))} -> Tinggi | F15: {=IF($I15="","",INDEX('Data Proyek'!$L$5:$L$204,MATCH($I15,'Data Proyek'!$W$5:$W$204,0)))} -> Berjalan | G15: =IF($I15="","",INT($I15)) -> 58 | H15: {=IF($I15="","",INDEX('Data Proyek'!$Q$5:$Q$204,MATCH($I15,'Data Proyek'!$W$5:$W$204,0)))} -> 6 | I15: =IFERROR(LARGE('Data Proyek'!$W$5:$W$204,7),"") -> 58.00005
A16: {=IF($I16="","",INDEX('Data Proyek'!$C$5:$C$204,MATCH($I16,'Data Proyek'!$W$5:$W$204,0)))} -> Batas Lahan dan Situasi | B16: {=IF($I16="","",INDEX('Data Proyek'!$B$5:$B$204,MATCH($I16,'Data Proyek'!$W$5:$W$204,0)))} -> JSI-ENT-JAS-001 | C16: {=IF($I16="","",INDEX('Data Proyek'!$D$5:$D$204,MATCH($I16,'Data Proyek'!$W$5:$W$204,0)))} -> PT Pertamina Zona 4 Prabumulih | D16: {=IF($I16="","",INDEX('Data Proyek'!$K$5:$K$204,MATCH($I16,'Data Proyek'!$W$5:$W$204,0)))} -> Rika | E16: {=IF($I16="","",INDEX('Data Proyek'!$T$5:$T$204,MATCH($I16,'Data Proyek'!$W$5:$W$204,0)))} -> Sedang | F16: {=IF($I16="","",INDEX('Data Proyek'!$L$5:$L$204,MATCH($I16,'Data Proyek'!$W$5:$W$204,0)))} -> Berjalan | G16: =IF($I16="","",INT($I16)) -> 53 | H16: {=IF($I16="","",INDEX('Data Proyek'!$Q$5:$Q$204,MATCH($I16,'Data Proyek'!$W$5:$W$204,0)))} -> 9 | I16: =IFERROR(LARGE('Data Proyek'!$W$5:$W$204,8),"") -> 53.00007
A17: {=IF($I17="","",INDEX('Data Proyek'!$C$5:$C$204,MATCH($I17,'Data Proyek'!$W$5:$W$204,0)))} -> Topografi LIDAR 700HA | B17: {=IF($I17="","",INDEX('Data Proyek'!$B$5:$B$204,MATCH($I17,'Data Proyek'!$W$5:$W$204,0)))} -> JSI-ENT-JAS-013 | C17: {=IF($I17="","",INDEX('Data Proyek'!$D$5:$D$204,MATCH($I17,'Data Proyek'!$W$5:$W$204,0)))} -> Helen, Dasep Ahmadi | D17: {=IF($I17="","",INDEX('Data Proyek'!$K$5:$K$204,MATCH($I17,'Data Proyek'!$W$5:$W$204,0)))} -> Harir | E17: {=IF($I17="","",INDEX('Data Proyek'!$T$5:$T$204,MATCH($I17,'Data Proyek'!$W$5:$W$204,0)))} -> Sedang | F17: {=IF($I17="","",INDEX('Data Proyek'!$L$5:$L$204,MATCH($I17,'Data Proyek'!$W$5:$W$204,0)))} -> Penawaran | G17: =IF($I17="","",INT($I17)) -> 52 | H17: {=IF($I17="","",INDEX('Data Proyek'!$Q$5:$Q$204,MATCH($I17,'Data Proyek'!$W$5:$W$204,0)))} | I17: =IFERROR(LARGE('Data Proyek'!$W$5:$W$204,9),"") -> 52.00019
A18: {=IF($I18="","",INDEX('Data Proyek'!$C$5:$C$204,MATCH($I18,'Data Proyek'!$W$5:$W$204,0)))} -> Topografi LiDAR 400HA | B18: {=IF($I18="","",INDEX('Data Proyek'!$B$5:$B$204,MATCH($I18,'Data Proyek'!$W$5:$W$204,0)))} -> JSI-ENT-JAS-012 | C18: {=IF($I18="","",INDEX('Data Proyek'!$D$5:$D$204,MATCH($I18,'Data Proyek'!$W$5:$W$204,0)))} -> PT Kungkilan Bukit Tengkiling | D18: {=IF($I18="","",INDEX('Data Proyek'!$K$5:$K$204,MATCH($I18,'Data Proyek'!$W$5:$W$204,0)))} -> Rika | E18: {=IF($I18="","",INDEX('Data Proyek'!$T$5:$T$204,MATCH($I18,'Data Proyek'!$W$5:$W$204,0)))} -> Sedang | F18: {=IF($I18="","",INDEX('Data Proyek'!$L$5:$L$204,MATCH($I18,'Data Proyek'!$W$5:$W$204,0)))} -> Penawaran | G18: =IF($I18="","",INT($I18)) -> 52 | H18: {=IF($I18="","",INDEX('Data Proyek'!$Q$5:$Q$204,MATCH($I18,'Data Proyek'!$W$5:$W$204,0)))} | I18: =IFERROR(LARGE('Data Proyek'!$W$5:$W$204,10),"") -> 52.00018
A20: REKAP PER DIVISI × JENIS PROYEK
A21: Divisi | B21: Jasa | C21: Penjualan | D21: Riset | E21: Training | F21: Total Proyek | G21: Nilai (Rp) | H21: Prioritas KRITIS
A22: =IF(Referensi!$A$5="","",Referensi!$A$5) -> Enterprise JSI | B22: =IF($A22="","",COUNTIFS('Data Proyek'!$I$5:$I$204,$A22,'Data Proyek'!$J$5:$J$204,Referensi!$D$5)) -> 13 | C22: =IF($A22="","",COUNTIFS('Data Proyek'!$I$5:$I$204,$A22,'Data Proyek'!$J$5:$J$204,Referensi!$D$6)) -> 2 | D22: =IF($A22="","",COUNTIFS('Data Proyek'!$I$5:$I$204,$A22,'Data Proyek'!$J$5:$J$204,Referensi!$D$7)) -> 2 | E22: =IF($A22="","",COUNTIFS('Data Proyek'!$I$5:$I$204,$A22,'Data Proyek'!$J$5:$J$204,Referensi!$D$8)) -> 0 | F22: =IF($A22="","",COUNTIF('Data Proyek'!$I$5:$I$204,$A22)) -> 17 | G22: =IF($A22="","",SUMIF('Data Proyek'!$I$5:$I$204,$A22,'Data Proyek'!$U$5:$U$204)) -> 11503854400 | H22: =IF($A22="","",COUNTIFS('Data Proyek'!$I$5:$I$204,$A22,'Data Proyek'!$T$5:$T$204,"KRITIS")) -> 0
A23: =IF(Referensi!$A$6="","",Referensi!$A$6) -> Consultant | B23: =IF($A23="","",COUNTIFS('Data Proyek'!$I$5:$I$204,$A23,'Data Proyek'!$J$5:$J$204,Referensi!$D$5)) -> 0 | C23: =IF($A23="","",COUNTIFS('Data Proyek'!$I$5:$I$204,$A23,'Data Proyek'!$J$5:$J$204,Referensi!$D$6)) -> 0 | D23: =IF($A23="","",COUNTIFS('Data Proyek'!$I$5:$I$204,$A23,'Data Proyek'!$J$5:$J$204,Referensi!$D$7)) -> 0 | E23: =IF($A23="","",COUNTIFS('Data Proyek'!$I$5:$I$204,$A23,'Data Proyek'!$J$5:$J$204,Referensi!$D$8)) -> 0 | F23: =IF($A23="","",COUNTIF('Data Proyek'!$I$5:$I$204,$A23)) -> 0 | G23: =IF($A23="","",SUMIF('Data Proyek'!$I$5:$I$204,$A23,'Data Proyek'!$U$5:$U$204)) -> 0 | H23: =IF($A23="","",COUNTIFS('Data Proyek'!$I$5:$I$204,$A23,'Data Proyek'!$T$5:$T$204,"KRITIS")) -> 0
A24: =IF(Referensi!$A$7="","",Referensi!$A$7) -> Retail | B24: =IF($A24="","",COUNTIFS('Data Proyek'!$I$5:$I$204,$A24,'Data Proyek'!$J$5:$J$204,Referensi!$D$5)) -> 0 | C24: =IF($A24="","",COUNTIFS('Data Proyek'!$I$5:$I$204,$A24,'Data Proyek'!$J$5:$J$204,Referensi!$D$6)) -> 0 | D24: =IF($A24="","",COUNTIFS('Data Proyek'!$I$5:$I$204,$A24,'Data Proyek'!$J$5:$J$204,Referensi!$D$7)) -> 0 | E24: =IF($A24="","",COUNTIFS('Data Proyek'!$I$5:$I$204,$A24,'Data Proyek'!$J$5:$J$204,Referensi!$D$8)) -> 0 | F24: =IF($A24="","",COUNTIF('Data Proyek'!$I$5:$I$204,$A24)) -> 0 | G24: =IF($A24="","",SUMIF('Data Proyek'!$I$5:$I$204,$A24,'Data Proyek'!$U$5:$U$204)) -> 0 | H24: =IF($A24="","",COUNTIFS('Data Proyek'!$I$5:$I$204,$A24,'Data Proyek'!$T$5:$T$204,"KRITIS")) -> 0
A25: TOTAL | B25: =SUM(B22:B24) -> 13 | C25: =SUM(C22:C24) -> 2 | D25: =SUM(D22:D24) -> 2 | E25: =SUM(E22:E24) -> 0 | F25: =SUM(F22:F24) -> 17 | G25: =SUM(G22:G24) -> 11503854400 | H25: =SUM(H22:H24) -> 0
A27: REKAP PER JENIS PROYEK
A28: Jenis Proyek | B28: Kode Jenis | C28: Jumlah Proyek | D28: Nilai (Rp) | E28: Prioritas KRITIS
A29: =IF(Referensi!$D$5="","",Referensi!$D$5) -> Jasa | B29: =IF($A29="","",Referensi!$E$5) -> JAS | C29: =IF($A29="","",COUNTIF('Data Proyek'!$J$5:$J$204,$A29)) -> 13 | D29: =IF($A29="","",SUMIF('Data Proyek'!$J$5:$J$204,$A29,'Data Proyek'!$U$5:$U$204)) -> 7318854400 | E29: =IF($A29="","",COUNTIFS('Data Proyek'!$J$5:$J$204,$A29,'Data Proyek'!$T$5:$T$204,"KRITIS")) -> 0
A30: =IF(Referensi!$D$6="","",Referensi!$D$6) -> Penjualan | B30: =IF($A30="","",Referensi!$E$6) -> PNJ | C30: =IF($A30="","",COUNTIF('Data Proyek'!$J$5:$J$204,$A30)) -> 2 | D30: =IF($A30="","",SUMIF('Data Proyek'!$J$5:$J$204,$A30,'Data Proyek'!$U$5:$U$204)) -> 4185000000 | E30: =IF($A30="","",COUNTIFS('Data Proyek'!$J$5:$J$204,$A30,'Data Proyek'!$T$5:$T$204,"KRITIS")) -> 0
A31: =IF(Referensi!$D$7="","",Referensi!$D$7) -> Riset | B31: =IF($A31="","",Referensi!$E$7) -> RIS | C31: =IF($A31="","",COUNTIF('Data Proyek'!$J$5:$J$204,$A31)) -> 2 | D31: =IF($A31="","",SUMIF('Data Proyek'!$J$5:$J$204,$A31,'Data Proyek'!$U$5:$U$204)) -> 0 | E31: =IF($A31="","",COUNTIFS('Data Proyek'!$J$5:$J$204,$A31,'Data Proyek'!$T$5:$T$204,"KRITIS")) -> 0
A32: =IF(Referensi!$D$8="","",Referensi!$D$8) -> Training | B32: =IF($A32="","",Referensi!$E$8) -> TRN | C32: =IF($A32="","",COUNTIF('Data Proyek'!$J$5:$J$204,$A32)) -> 0 | D32: =IF($A32="","",SUMIF('Data Proyek'!$J$5:$J$204,$A32,'Data Proyek'!$U$5:$U$204)) -> 0 | E32: =IF($A32="","",COUNTIFS('Data Proyek'!$J$5:$J$204,$A32,'Data Proyek'!$T$5:$T$204,"KRITIS")) -> 0
A35: REKAP PER PIC / PENANGGUNG JAWAB
A36: PIC | B36: Total Proyek | C36: Nilai (Rp) | D36: Prioritas KRITIS | E36: Deadline Terlewat
A37: =IF(Referensi!$G$5="","",Referensi!$G$5) -> Harir | B37: =IF($A37="","",COUNTIF('Data Proyek'!$K$5:$K$204,$A37)) -> 5 | C37: =IF($A37="","",SUMIF('Data Proyek'!$K$5:$K$204,$A37,'Data Proyek'!$U$5:$U$204)) -> 913139900 | D37: =IF($A37="","",COUNTIFS('Data Proyek'!$K$5:$K$204,$A37,'Data Proyek'!$T$5:$T$204,"KRITIS")) -> 0 | E37: =IF($A37="","",COUNTIFS('Data Proyek'!$K$5:$K$204,$A37,'Data Proyek'!$Q$5:$Q$204,"<0")) -> 0
A38: =IF(Referensi!$G$6="","",Referensi!$G$6) -> Nurdiyansah | B38: =IF($A38="","",COUNTIF('Data Proyek'!$K$5:$K$204,$A38)) -> 3 | C38: =IF($A38="","",SUMIF('Data Proyek'!$K$5:$K$204,$A38,'Data Proyek'!$U$5:$U$204)) -> 3053300000 | D38: =IF($A38="","",COUNTIFS('Data Proyek'!$K$5:$K$204,$A38,'Data Proyek'!$T$5:$T$204,"KRITIS")) -> 0 | E38: =IF($A38="","",COUNTIFS('Data Proyek'!$K$5:$K$204,$A38,'Data Proyek'!$Q$5:$Q$204,"<0")) -> 0
A39: =IF(Referensi!$G$7="","",Referensi!$G$7) -> Rika | B39: =IF($A39="","",COUNTIF('Data Proyek'!$K$5:$K$204,$A39)) -> 9 | C39: =IF($A39="","",SUMIF('Data Proyek'!$K$5:$K$204,$A39,'Data Proyek'!$U$5:$U$204)) -> 7537414500 | D39: =IF($A39="","",COUNTIFS('Data Proyek'!$K$5:$K$204,$A39,'Data Proyek'!$T$5:$T$204,"KRITIS")) -> 0 | E39: =IF($A39="","",COUNTIFS('Data Proyek'!$K$5:$K$204,$A39,'Data Proyek'!$Q$5:$Q$204,"<0")) -> 0
A40: =IF(Referensi!$G$8="","",Referensi!$G$8) -> Nama PIC 4 | B40: =IF($A40="","",COUNTIF('Data Proyek'!$K$5:$K$204,$A40)) -> 0 | C40: =IF($A40="","",SUMIF('Data Proyek'!$K$5:$K$204,$A40,'Data Proyek'!$U$5:$U$204)) -> 0 | D40: =IF($A40="","",COUNTIFS('Data Proyek'!$K$5:$K$204,$A40,'Data Proyek'!$T$5:$T$204,"KRITIS")) -> 0 | E40: =IF($A40="","",COUNTIFS('Data Proyek'!$K$5:$K$204,$A40,'Data Proyek'!$Q$5:$Q$204,"<0")) -> 0
A41: =IF(Referensi!$G$9="","",Referensi!$G$9) -> Nama PIC 5 | B41: =IF($A41="","",COUNTIF('Data Proyek'!$K$5:$K$204,$A41)) -> 0 | C41: =IF($A41="","",SUMIF('Data Proyek'!$K$5:$K$204,$A41,'Data Proyek'!$U$5:$U$204)) -> 0 | D41: =IF($A41="","",COUNTIFS('Data Proyek'!$K$5:$K$204,$A41,'Data Proyek'!$T$5:$T$204,"KRITIS")) -> 0 | E41: =IF($A41="","",COUNTIFS('Data Proyek'!$K$5:$K$204,$A41,'Data Proyek'!$Q$5:$Q$204,"<0")) -> 0
A42: =IF(Referensi!$G$10="","",Referensi!$G$10) -> Nama PIC 6 | B42: =IF($A42="","",COUNTIF('Data Proyek'!$K$5:$K$204,$A42)) -> 0 | C42: =IF($A42="","",SUMIF('Data Proyek'!$K$5:$K$204,$A42,'Data Proyek'!$U$5:$U$204)) -> 0 | D42: =IF($A42="","",COUNTIFS('Data Proyek'!$K$5:$K$204,$A42,'Data Proyek'!$T$5:$T$204,"KRITIS")) -> 0 | E42: =IF($A42="","",COUNTIFS('Data Proyek'!$K$5:$K$204,$A42,'Data Proyek'!$Q$5:$Q$204,"<0")) -> 0
A43: =IF(Referensi!$G$11="","",Referensi!$G$11) -> Nama PIC 7 | B43: =IF($A43="","",COUNTIF('Data Proyek'!$K$5:$K$204,$A43)) -> 0 | C43: =IF($A43="","",SUMIF('Data Proyek'!$K$5:$K$204,$A43,'Data Proyek'!$U$5:$U$204)) -> 0 | D43: =IF($A43="","",COUNTIFS('Data Proyek'!$K$5:$K$204,$A43,'Data Proyek'!$T$5:$T$204,"KRITIS")) -> 0 | E43: =IF($A43="","",COUNTIFS('Data Proyek'!$K$5:$K$204,$A43,'Data Proyek'!$Q$5:$Q$204,"<0")) -> 0
A44: =IF(Referensi!$G$12="","",Referensi!$G$12) -> Nama PIC 8 | B44: =IF($A44="","",COUNTIF('Data Proyek'!$K$5:$K$204,$A44)) -> 0 | C44: =IF($A44="","",SUMIF('Data Proyek'!$K$5:$K$204,$A44,'Data Proyek'!$U$5:$U$204)) -> 0 | D44: =IF($A44="","",COUNTIFS('Data Proyek'!$K$5:$K$204,$A44,'Data Proyek'!$T$5:$T$204,"KRITIS")) -> 0 | E44: =IF($A44="","",COUNTIFS('Data Proyek'!$K$5:$K$204,$A44,'Data Proyek'!$Q$5:$Q$204,"<0")) -> 0
A45: TOTAL | B45: =SUM(B37:B44) -> 17 | C45: =SUM(C37:C44) -> 11503854400 | D45: =SUM(D37:D44) -> 0 | E45: =SUM(E37:E44) -> 0
A47: REKAP PER LEVEL PRIORITAS
...

Sheet Referensi
A1: DAFTAR REFERENSI & PARAMETER
A2: Semua dropdown, kode proyek, dan perhitungan prioritas di sheet 'Data Proyek' mengambil dari sini. Ubah isi sel sesuai kondisi tim — rumus menyesuaikan otomatis.
A4: Divisi | B4: Kode Divisi | D4: Jenis Proyek | E4: Kode Jenis | G4: PIC / Penanggung Jawab | I4: Status Proyek | K4: Provinsi | M4: Klien / Instansi | O4: Parameter Kriteria Prioritas | P4: Nilai
A5: Enterprise JSI | B5: ENT | D5: Jasa | E5: JAS | G5: Harir | I5: Prospek | K5: Jawa Tengah | M5: Balai Besar Pelaksanaan Jalan Nasional | O5: Deadline: sisa hari <= ini → sangat kritis | P5: 7
A6: Consultant | B6: CON | D6: Penjualan | E6: PNJ | G6: Nurdiyansah | I6: Penawaran | K6: Jawa Timur | M6: PT Pelindo | O6: Deadline: sisa hari <= ini → mendesak | P6: 14
A7: Retail | B7: RTL | D7: Riset | E7: RIS | G7: Rika | I7: Negosiasi | K7: Jawa Barat | M7: Kantor Pertanahan (BPN) | O7: Deadline: sisa hari <= ini → waspada | P7: 30
D8: Training | E8: TRN | G8: Nama PIC 4 | I8: Berjalan | K8: DKI Jakarta | M8: Universitas Diponegoro | O8: Kontak: lebih dari ini (hari) → terlalu lama | P8: 30
G9: Nama PIC 5 | I9: Selesai | K9: Banten | M9: Klien 5 | O9: Kontak: lebih dari ini (hari) → perlu dipantau | P9: 14
G10: Nama PIC 6 | I10: Tertunda | K10: DI Yogyakarta | M10: Klien 6 | O10: Nilai proyek dianggap BESAR (Rp) | P10: 500000000
G11: Nama PIC 7 | I11: Batal | K11: Kalimantan Timur | M11: Klien 7 | O11: Nilai proyek dianggap SEDANG (Rp) | P11: 100000000
G12: Nama PIC 8 | K12: Sulawesi Selatan | M12: Klien 8 | O12: Ambang skor → level KRITIS | P12: 75
K13: Sumatera Utara | M13: Klien 9 | O13: Ambang skor → level Tinggi | P13: 55
K14: Bali | M14: Klien 10 | O14: Ambang skor → level Sedang | P14: 35
O16: Sel kuning = angka asumsi, boleh diubah. KODE PROYEK dirakit sebagai JSI-<Kode Divisi>-<Kode Jenis>-<nomor urut>, contoh JSI-ENT-JAS-001. Nomor urut dihitung terpisah untuk tiap kombinasi divisi + jenis.

Sheet Data Proyek
A1: DATA PROYEK — PT JAYA SURVEI INDONESIA
A2: PETUNJUK: isi hanya kolom berlatar putih. Kolom abu-abu terisi otomatis — jangan diketik manual. Kode Proyek terbentuk sendiri setelah kolom Divisi dan Jenis diisi. Baris 5–8 adalah contoh; hapus isinya sebelum dipakai, biarkan rumusnya.
A4: No | B4: Kode Proyek | C4: Nama Proyek | D4: Klien / Instansi | E4: Nama Kontak Klien | F4: No. HP Klien | G4: Lokasi (Kota/Kab.) | H4: Provinsi | I4: Divisi | J4: Jenis | K4: PIC | L4: Status | M4: Tgl Mulai | N4: Tgl Target Selesai | O4: Tgl Kontak Terakhir | P4: Selisih Kontak (hari) | Q4: Sisa Hari ke Deadline | R4: Tindak Lanjut | S4: Skor Prioritas | T4: Level Prioritas | U4: Nilai Proyek (Rp) | V4: Deskripsi Pekerjaan | W4: _urut
A5: =IF($C5="","",ROW()-4) -> 1 | B5: {=IF(OR($C5="",$I5="",$J5=""),"","JSI-"&IFERROR(INDEX(Referensi!$B$5:$B$14,MATCH($I5,Referensi!$A$5:$A$14,0)),"???")&"-"&IFERROR(INDEX(Referensi!$E$5:$E$14,MATCH($J5,Referensi!$D$5:$D$14,0)),"???")&"-"&TEXT(COUNTIFS($I$5:$I5,$I5,$J$5:$J5,$J5),"000"))} -> JSI-ENT-RIS-001 | C5: Riset Carbon Stock | D5: Undip | G5: Semarang | H5: Jawa Tengah | I5: Enterprise JSI | J5: Riset | K5: Harir | L5: Berjalan | M5: 46264 | N5: 46268 | O5: 46262 | P5: =IF(OR($C5="",$O5=""),"",TODAY()-$O5) -> 0 | Q5: =IF(OR($C5="",$N5=""),"",$N5-TODAY()) -> 6 | R5: =IF($C5="","",IF($O5="","Belum ada kontak",IF($P5>Referensi!$P$8,"Segera follow up",IF($P5>Referensi!$P$9,"Perlu dipantau","Terkini")))) -> Terkini | S5: =IF($C5="","",IF(OR($L5="Selesai",$L5="Batal"),0,IF($Q5="",5,IF($Q5<0,50,IF($Q5<=Referensi!$P$5,40,IF($Q5<=Referensi!$P$6,30,IF($Q5<=Referensi!$P$7,20,10)))))+IF($O5="",25,IF($P5>Referensi!$P$8,30,IF($P5>Referensi!$P$9,20,5)))+IF($U5="",5,IF($U5>=Referensi!$P$10,20,IF($U5>=Referensi!$P$11,10,5)))+IF($L5="Tertunda",15,IF(OR($L5="Negosiasi",$L5="Penawaran"),12,IF($L5="Berjalan",8,IF($L5="Prospek",5,0)))))) -> 58 | T5: =IF($C5="","",IF(OR($L5="Selesai",$L5="Batal"),"Tidak aktif",IF($S5>=Referensi!$P$12,"KRITIS",IF($S5>=Referensi!$P$13,"Tinggi",IF($S5>=Referensi!$P$14,"Sedang","Rendah"))))) -> Tinggi | U5: 0 | V5: Riset mengenai penggunaan SLAM LiDAR Untuk perhitungan Carbon Stock | W5: =IF(OR($C5="",$T5="Tidak aktif"),"",$S5+ROW()/100000) -> 58.00005
A6: =IF($C6="","",ROW()-4) -> 2 | B6: {=IF(OR($C6="",$I6="",$J6=""),"","JSI-"&IFERROR(INDEX(Referensi!$B$5:$B$14,MATCH($I6,Referensi!$A$5:$A$14,0)),"???")&"-"&IFERROR(INDEX(Referensi!$E$5:$E$14,MATCH($J6,Referensi!$D$5:$D$14,0)),"???")&"-"&TEXT(COUNTIFS($I$5:$I6,$I6,$J$5:$J6,$J6),"000"))} -> JSI-ENT-RIS-002 | C6: MOU ITERA | D6: ITERA | E6: Ulin | G6: Lampung | H6: Lampung | I6: Enterprise JSI | J6: Riset | K6: Harir | L6: Berjalan | M6: 46272 | N6: 46272 | O6: 46262 | P6: =IF(OR($C6="",$O6=""),"",TODAY()-$O6) -> 0 | Q6: =IF(OR($C6="",$N6=""),"",$N6-TODAY()) -> 10 | R6: =IF($C6="","",IF($O6="","Belum ada kontak",IF($P6>Referensi!$P$8,"Segera follow up",IF($P6>Referensi!$P$9,"Perlu dipantau","Terkini")))) -> Terkini | S6: =IF($C6="","",IF(OR($L6="Selesai",$L6="Batal"),0,IF($Q6="",5,IF($Q6<0,50,IF($Q6<=Referensi!$P$5,40,IF($Q6<=Referensi!$P$6,30,IF($Q6<=Referensi!$P$7,20,10)))))+IF($O6="",25,IF($P6>Referensi!$P$8,30,IF($P6>Referensi!$P$9,20,5)))+IF($U6="",5,IF($U6>=Referensi!$P$10,20,IF($U6>=Referensi!$P$11,10,5)))+IF($L6="Tertunda",15,IF(OR($L6="Negosiasi",$L6="Penawaran"),12,IF($L6="Berjalan",8,IF($L6="Prospek",5,0)))))) -> 48 | T6: =IF($C6="","",IF(OR($L6="Selesai",$L6="Batal"),"Tidak aktif",IF($S6>=Referensi!$P$12,"KRITIS",IF($S6>=Referensi!$P$13,"Tinggi",IF($S6>=Referensi!$P$14,"Sedang","Rendah"))))) -> Sedang | U6: 0 | V6: MOU Terkait riset dan training dengan Teknik Geomatik ITERA | W6: =IF(OR($C6="",$T6="Tidak aktif"),"",$S6+ROW()/100000) -> 48.00006
A7: =IF($C7="","",ROW()-4) -> 3 | B7: {=IF(OR($C7="",$I7="",$J7=""),"","JSI-"&IFERROR(INDEX(Referensi!$B$5:$B$14,MATCH($I7,Referensi!$A$5:$A$14,0)),"???")&"-"&IFERROR(INDEX(Referensi!$E$5:$E$14,MATCH($J7,Referensi!$D$5:$D$14,0)),"???")&"-"&TEXT(COUNTIFS($I$5:$I7,$I7,$J$5:$J7,$J7),"000"))} -> JSI-ENT-JAS-001 | C7: Batas Lahan dan Situasi | D7: PT Pertamina Zona 4 Prabumulih | E7: Ilham habibie | F7: 085210207730 | G7: Prabumulih | H7: Sumatera Selatan | I7: Enterprise JSI | J7: Jasa | K7: Rika | L7: Berjalan | M7: 46209 | N7: 46271 | O7: 46271 | P7: =IF(OR($C7="",$O7=""),"",TODAY()-$O7) -> -9 | Q7: =IF(OR($C7="",$N7=""),"",$N7-TODAY()) -> 9 | R7: =IF($C7="","",IF($O7="","Belum ada kontak",IF($P7>Referensi!$P$8,"Segera follow up",IF($P7>Referensi!$P$9,"Perlu dipantau","Terkini")))) -> Terkini | S7: =IF($C7="","",IF(OR($L7="Selesai",$L7="Batal"),0,IF($Q7="",5,IF($Q7<0,50,IF($Q7<=Referensi!$P$5,40,IF($Q7<=Referensi!$P$6,30,IF($Q7<=Referensi!$P$7,20,10)))))+IF($O7="",25,IF($P7>Referensi!$P$8,30,IF($P7>Referensi!$P$9,20,5)))+IF($U7="",5,IF($U7>=Referensi!$P$10,20,IF($U7>=Referensi!$P$11,10,5)))+IF($L7="Tertunda",15,IF(OR($L7="Negosiasi",$L7="Penawaran"),12,IF($L7="Berjalan",8,IF($L7="Prospek",5,0)))))) -> 53 | T7: =IF($C7="","",IF(OR($L7="Selesai",$L7="Batal"),"Tidak aktif",IF($S7>=Referensi!$P$12,"KRITIS",IF($S7>=Referensi!$P$13,"Tinggi",IF($S7>=Referensi!$P$14,"Sedang","Rendah"))))) -> Sedang | U7: 152100000 | V7: Jasa Pengukuran Topografi Batas Lahan dan Situasi Area Komplek Pertamina Zona 4 Prabumulih | W7: =IF(OR($C7="",$T7="Tidak aktif"),"",$S7+ROW()/100000) -> 53.00007
A8: =IF($C8="","",ROW()-4) -> 4 | B8: {=IF(OR($C8="",$I8="",$J8=""),"","JSI-"&IFERROR(INDEX(Referensi!$B$5:$B$14,MATCH($I8,Referensi!$A$5:$A$14,0)),"???")&"-"&IFERROR(INDEX(Referensi!$E$5:$E$14,MATCH($J8,Referensi!$D$5:$D$14,0)),"???")&"-"&TEXT(COUNTIFS($I$5:$I8,$I8,$J$5:$J8,$J8),"000"))} -> JSI-ENT-JAS-002 | C8: Topografi LiDAR PLTA Medan Aceh | D8: Saris Geoterra | E8: Saris | F8: 085378676656 | G8: Medan, Aceh | H8: Sumatera Utara | I8: Enterprise JSI | J8: Jasa | K8: Rika | L8: Negosiasi | P8: =IF(OR($C8="",$O8=""),"",TODAY()-$O8) | Q8: =IF(OR($C8="",$N8=""),"",$N8-TODAY()) | R8: =IF($C8="","",IF($O8="","Belum ada kontak",IF($P8>Referensi!$P$8,"Segera follow up",IF($P8>Referensi!$P$9,"Perlu dipantau","Terkini")))) -> Belum ada kontak | S8: =IF($C8="","",IF(OR($L8="Selesai",$L8="Batal"),0,IF($Q8="",5,IF($Q8<0,50,IF($Q8<=Referensi!$P$5,40,IF($Q8<=Referensi!$P$6,30,IF($Q8<=Referensi!$P$7,20,10)))))+IF($O8="",25,IF($P8>Referensi!$P$8,30,IF($P8>Referensi!$P$9,20,5)))+IF($U8="",5,IF($U8>=Referensi!$P$10,20,IF($U8>=Referensi!$P$11,10,5)))+IF($L8="Tertunda",15,IF(OR($L8="Negosiasi",$L8="Penawaran"),12,IF($L8="Berjalan",8,IF($L8="Prospek",5,0)))))) -> 52 | T8: =IF($C8="","",IF(OR($L8="Selesai",$L8="Batal"),"Tidak aktif",IF($S8>=Referensi!$P$12,"KRITIS",IF($S8>=Referensi!$P$13,"Tinggi",IF($S8>=Referensi!$P$14,"Sedang","Rendah"))))) -> Sedang | U8: =193567500+275454000 -> 469021500 | V8: Topografi Lidar PLTA 440 ha dan 846Ha | W8: =IF(OR($C8="",$T8="Tidak aktif"),"",$S8+ROW()/100000) -> 52.00008
A9: =IF($C9="","",ROW()-4) -> 5 | B9: {=IF(OR($C9="",$I9="",$J9=""),"","JSI-"&IFERROR(INDEX(Referensi!$B$5:$B$14,MATCH($I9,Referensi!$A$5:$A$14,0)),"???")&"-"&IFERROR(INDEX(Referensi!$E$5:$E$14,MATCH($J9,Referensi!$D$5:$D$14,0)),"???")&"-"&TEXT(COUNTIFS($I$5:$I9,$I9,$J$5:$J9,$J9),"000"))} -> JSI-ENT-JAS-003 | C9: Topografi LiDAR 9000 HA | D9: PT Sriwijaya Tansri Energi | G9: Muara Enim | H9: Sumatera Selatan | I9: Enterprise JSI | J9: Jasa | K9: Nurdiyansah | L9: Penawaran | P9: =IF(OR($C9="",$O9=""),"",TODAY()-$O9) | Q9: =IF(OR($C9="",$N9=""),"",$N9-TODAY()) | R9: =IF($C9="","",IF($O9="","Belum ada kontak",IF($P9>Referensi!$P$8,"Segera follow up",IF($P9>Referensi!$P$9,"Perlu dipantau","Terkini")))) -> Belum ada kontak | S9: =IF($C9="","",IF(OR($L9="Selesai",$L9="Batal"),0,IF($Q9="",5,IF($Q9<0,50,IF($Q9<=Referensi!$P$5,40,IF($Q9<=Referensi!$P$6,30,IF($Q9<=Referensi!$P$7,20,10)))))+IF($O9="",25,IF($P9>Referensi!$P$8,30,IF($P9>Referensi!$P$9,20,5)))+IF($U9="",5,IF($U9>=Referensi!$P$10,20,IF($U9>=Referensi!$P$11,10,5)))+IF($L9="Tertunda",15,IF(OR($L9="Negosiasi",$L9="Penawaran"),12,IF($L9="Berjalan",8,IF($L9="Prospek",5,0)))))) -> 62 | T9: =IF($C9="","",IF(OR($L9="Selesai",$L9="Batal"),"Tidak aktif",IF($S9>=Referensi!$P$12,"KRITIS",IF($S9>=Referensi!$P$13,"Tinggi",IF($S9>=Referensi!$P$14,"Sedang","Rendah"))))) -> Tinggi | U9: 2205450000 | V9: Topografi Lidar | W9: =IF(OR($C9="",$T9="Tidak aktif"),"",$S9+ROW()/100000) -> 62.00009
A10: =IF($C10="","",ROW()-4) -> 6 | B10: {=IF(OR($C10="",$I10="",$J10=""),"","JSI-"&IFERROR(INDEX(Referensi!$B$5:$B$14,MATCH($I10,Referensi!$A$5:$A$14,0)),"???")&"-"&IFERROR(INDEX(Referensi!$E$5:$E$14,MATCH($J10,Referensi!$D$5:$D$14,0)),"???")&"-"&TEXT(COUNTIFS($I$5:$I10,$I10,$J$5:$J10,$J10),"000"))} -> JSI-ENT-JAS-004 | C10: Topografi LiDAR 4500 HA | D10: PT Sriwijaya Tansri Energi | G10: Muara Enim | H10: Sumatera Selatan | I10: Enterprise JSI | J10: Jasa | K10: Nurdiyansah | L10: Penawaran | P10: =IF(OR($C10="",$O10=""),"",TODAY()-$O10) | Q10: =IF(OR($C10="",$N10=""),"",$N10-TODAY()) | R10: =IF($C10="","",IF($O10="","Belum ada kontak",IF($P10>Referensi!$P$8,"Segera follow up",IF($P10>Referensi!$P$9,"Perlu dipantau","Terkini")))) -> Belum ada kontak | S10: =IF($C10="","",IF(OR($L10="Selesai",$L10="Batal"),0,IF($Q10="",5,IF($Q10<0,50,IF($Q10<=Referensi!$P$5,40,IF($Q10<=Referensi!$P$6,30,IF($Q10<=Referensi!$P$7,20,10)))))+IF($O10="",25,IF($P10>Referensi!$P$8,30,IF($P10>Referensi!$P$9,20,5)))+IF($U10="",5,IF($U10>=Referensi!$P$10,20,IF($U10>=Referensi!$P$11,10,5)))+IF($L10="Tertunda",15,IF(OR($L10="Negosiasi",$L10="Penawaran"),12,IF($L10="Berjalan",8,IF($L10="Prospek",5,0)))))) -> 62 | T10: =IF($C10="","",IF(OR($L10="Selesai",$L10="Batal"),"Tidak aktif",IF($S10>=Referensi!$P$12,"KRITIS",IF($S10>=Referensi!$P$13,"Tinggi",IF($S10>=Referensi!$P$14,"Sedang","Rendah"))))) -> Tinggi | U10: 797850000 | V10: Topografi Lidar | W10: =IF(OR($C10="",$T10="Tidak aktif"),"",$S10+ROW()/100000) -> 62.0001
A11: =IF($C11="","",ROW()-4) -> 7 | B11: {=IF(OR($C11="",$I11="",$J11=""),"","JSI-"&IFERROR(INDEX(Referensi!$B$5:$B$14,MATCH($I11,Referensi!$A$5:$A$14,0)),"???")&"-"&IFERROR(INDEX(Referensi!$E$5:$E$14,MATCH($J11,Referensi!$D$5:$D$14,0)),"???")&"-"&TEXT(COUNTIFS($I$5:$I11,$I11,$J$5:$J11,$J11),"000"))} -> JSI-ENT-JAS-005 | C11: Topografi LIDAR 2762HA | D11: PT Geoffrey Asia Energy | E11: Candra | F11: 081253652680 | G11: Ketapang, | H11: Kalimantan Barat | I11: Enterprise JSI | J11: Jasa | K11: Rika | L11: Penawaran | P11: =IF(OR($C11="",$O11=""),"",TODAY()-$O11) | Q11: =IF(OR($C11="",$N11=""),"",$N11-TODAY()) | R11: =IF($C11="","",IF($O11="","Belum ada kontak",IF($P11>Referensi!$P$8,"Segera follow up",IF($P11>Referensi!$P$9,"Perlu dipantau","Terkini")))) -> Belum ada kontak | S11: =IF($C11="","",IF(OR($L11="Selesai",$L11="Batal"),0,IF($Q11="",5,IF($Q11<0,50,IF($Q11<=Referensi!$P$5,40,IF($Q11<=Referensi!$P$6,30,IF($Q11<=Referensi!$P$7,20,10)))))+IF($O11="",25,IF($P11>Referensi!$P$8,30,IF($P11>Referensi!$P$9,20,5)))+IF($U11="",5,IF($U11>=Referensi!$P$10,20,IF($U11>=Referensi!$P$11,10,5)))+IF($L11="Tertunda",15,IF(OR($L11="Negosiasi",$L11="Penawaran"),12,IF($L11="Berjalan",8,IF($L11="Prospek",5,0)))))) -> 52 | T11: =IF($C11="","",IF(OR($L11="Selesai",$L11="Batal"),"Tidak aktif",IF($S11>=Referensi!$P$12,"KRITIS",IF($S11>=Referensi!$P$13,"Tinggi",IF($S11>=Referensi!$P$14,"Sedang","Rendah"))))) -> Sedang | U11: 373735000 | V11: Topografi Lidar | W11: =IF(OR($C11="",$T11="Tidak aktif"),"",$S11+ROW()/100000) -> 52.00011
A12: =IF($C12="","",ROW()-4) -> 8 | B12: {=IF(OR($C12="",$I12="",$J12=""),"","JSI-"&IFERROR(INDEX(Referensi!$B$5:$B$14,MATCH($I12,Referensi!$A$5:$A$14,0)),"???")&"-"&IFERROR(INDEX(Referensi!$E$5:$E$14,MATCH($J12,Referensi!$D$5:$D$14,0)),"???")&"-"&TEXT(COUNTIFS($I$5:$I12,$I12,$J$5:$J12,$J12),"000"))} -> JSI-ENT-JAS-006 | C12: Topografi LiDAR 1500Ha | D12: IBIP | E12: Zuria Hidayat | G12: Bintan | H12: Kepri | I12: Enterprise JSI | J12: Jasa | K12: Harir | L12: Penawaran | P12: =IF(OR($C12="",$O12=""),"",TODAY()-$O12) | Q12: =IF(OR($C12="",$N12=""),"",$N12-TODAY()) | R12: =IF($C12="","",IF($O12="","Belum ada kontak",IF($P12>Referensi!$P$8,"Segera follow up",IF($P12>Referensi!$P$9,"Perlu dipantau","Terkini")))) -> Belum ada kontak | S12: =IF($C12="","",IF(OR($L12="Selesai",$L12="Batal"),0,IF($Q12="",5,IF($Q12<0,50,IF($Q12<=Referensi!$P$5,40,IF($Q12<=Referensi!$P$6,30,IF($Q12<=Referensi!$P$7,20,10)))))+IF($O12="",25,IF($P12>Referensi!$P$8,30,IF($P12>Referensi!$P$9,20,5)))+IF($U12="",5,IF($U12>=Referensi!$P$10,20,IF($U12>=Referensi!$P$11,10,5)))+IF($L12="Tertunda",15,IF(OR($L12="Negosiasi",$L12="Penawaran"),12,IF($L12="Berjalan",8,IF($L12="Prospek",5,0)))))) -> 52 | T12: =IF($C12="","",IF(OR($L12="Selesai",$L12="Batal"),"Tidak aktif",IF($S12>=Referensi!$P$12,"KRITIS",IF($S12>=Referensi!$P$13,"Tinggi",IF($S12>=Referensi!$P$14,"Sedang","Rendah"))))) -> Sedang | U12: 327616500 | V12: Topografi Lidar | W12: =IF(OR($C12="",$T12="Tidak aktif"),"",$S12+ROW()/100000) -> 52.00012
A13: =IF($C13="","",ROW()-4) -> 9 | B13: {=IF(OR($C13="",$I13="",$J13=""),"","JSI-"&IFERROR(INDEX(Referensi!$B$5:$B$14,MATCH($I13,Referensi!$A$5:$A$14,0)),"???")&"-"&IFERROR(INDEX(Referensi!$E$5:$E$14,MATCH($J13,Referensi!$D$5:$D$14,0)),"???")&"-"&TEXT(COUNTIFS($I$5:$I13,$I13,$J$5:$J13,$J13),"000"))} -> JSI-ENT-JAS-007 | C13: Topografi LiDAR 7000Ha | D13: PT Bhaktiputra Persada Nusantara | E13: Masdar | G13: Morowali Utara | H13: Sulawesi Tengah | I13: Enterprise JSI | J13: Jasa | K13: Rika | L13: Penawaran | P13: =IF(OR($C13="",$O13=""),"",TODAY()-$O13) | Q13: =IF(OR($C13="",$N13=""),"",$N13-TODAY()) | R13: =IF($C13="","",IF($O13="","Belum ada kontak",IF($P13>Referensi!$P$8,"Segera follow up",IF($P13>Referensi!$P$9,"Perlu dipantau","Terkini")))) -> Belum ada kontak | S13: =IF($C13="","",IF(OR($L13="Selesai",$L13="Batal"),0,IF($Q13="",5,IF($Q13<0,50,IF($Q13<=Referensi!$P$5,40,IF($Q13<=Referensi!$P$6,30,IF($Q13<=Referensi!$P$7,20,10)))))+IF($O13="",25,IF($P13>Referensi!$P$8,30,IF($P13>Referensi!$P$9,20,5)))+IF($U13="",5,IF($U13>=Referensi!$P$10,20,IF($U13>=Referensi!$P$11,10,5)))+IF($L13="Tertunda",15,IF(OR($L13="Negosiasi",$L13="Penawaran"),12,IF($L13="Berjalan",8,IF($L13="Prospek",5,0)))))) -> 62 | T13: =IF($C13="","",IF(OR($L13="Selesai",$L13="Batal"),"Tidak aktif",IF($S13>=Referensi!$P$12,"KRITIS",IF($S13>=Referensi!$P$13,"Tinggi",IF($S13>=Referensi!$P$14,"Sedang","Rendah"))))) -> Tinggi | U13: 973969500 | V13: Topografi Lidar | W13: =IF(OR($C13="",$T13="Tidak aktif"),"",$S13+ROW()/100000) -> 62.00013
A14: =IF($C14="","",ROW()-4) -> 10 | B14: {=IF(OR($C14="",$I14="",$J14=""),"","JSI-"&IFERROR(INDEX(Referensi!$B$5:$B$14,MATCH($I14,Referensi!$A$5:$A$14,0)),"???")&"-"&IFERROR(INDEX(Referensi!$E$5:$E$14,MATCH($J14,Referensi!$D$5:$D$14,0)),"???")&"-"&TEXT(COUNTIFS($I$5:$I14,$I14,$J$5:$J14,$J14),"000"))} -> JSI-ENT-JAS-008 | C14: Topografi Foto Udara | D14: PT Trimata Coal Perkasa | E14: Karta Sudarso | G14: Musi Banyuasin | H14: Sumatera Selatan | I14: Enterprise JSI | J14: Jasa | K14: Rika | L14: Negosiasi | P14: =IF(OR($C14="",$O14=""),"",TODAY()-$O14) | Q14: =IF(OR($C14="",$N14=""),"",$N14-TODAY()) | R14: =IF($C14="","",IF($O14="","Belum ada kontak",IF($P14>Referensi!$P$8,"Segera follow up",IF($P14>Referensi!$P$9,"Perlu dipantau","Terkini")))) -> Belum ada kontak | S14: =IF($C14="","",IF(OR($L14="Selesai",$L14="Batal"),0,IF($Q14="",5,IF($Q14<0,50,IF($Q14<=Referensi!$P$5,40,IF($Q14<=Referensi!$P$6,30,IF($Q14<=Referensi!$P$7,20,10)))))+IF($O14="",25,IF($P14>Referensi!$P$8,30,IF($P14>Referensi!$P$9,20,5)))+IF($U14="",5,IF($U14>=Referensi!$P$10,20,IF($U14>=Referensi!$P$11,10,5)))+IF($L14="Tertunda",15,IF(OR($L14="Negosiasi",$L14="Penawaran"),12,IF($L14="Berjalan",8,IF($L14="Prospek",5,0)))))) -> 62 | T14: =IF($C14="","",IF(OR($L14="Selesai",$L14="Batal"),"Tidak aktif",IF($S14>=Referensi!$P$12,"KRITIS",IF($S14>=Referensi!$P$13,"Tinggi",IF($S14>=Referensi!$P$14,"Sedang","Rendah"))))) -> Tinggi | U14: 1131700500 | V14: Topografi Foto Udara | W14: =IF(OR($C14="",$T14="Tidak aktif"),"",$S14+ROW()/100000) -> 62.00014
A15: =IF($C15="","",ROW()-4) -> 11 | B15: {=IF(OR($C15="",$I15="",$J15=""),"","JSI-"&IFERROR(INDEX(Referensi!$B$5:$B$14,MATCH($I15,Referensi!$A$5:$A$14,0)),"???")&"-"&IFERROR(INDEX(Referensi!$E$5:$E$14,MATCH($J15,Referensi!$D$5:$D$14,0)),"???")&"-"&TEXT(COUNTIFS($I$5:$I15,$I15,$J$5:$J15,$J15),"000"))} -> JSI-ENT-JAS-009 | C15: Survei GPR 7 KM | D15: Sufyan | F15: 081356001212 | G15: Makassar | H15: Sulawesi Selatan | I15: Enterprise JSI | J15: Jasa | K15: Rika | L15: Penawaran | P15: =IF(OR($C15="",$O15=""),"",TODAY()-$O15) | Q15: =IF(OR($C15="",$N15=""),"",$N15-TODAY()) | R15: =IF($C15="","",IF($O15="","Belum ada kontak",IF($P15>Referensi!$P$8,"Segera follow up",IF($P15>Referensi!$P$9,"Perlu dipantau","Terkini")))) -> Belum ada kontak | S15: =IF($C15="","",IF(OR($L15="Selesai",$L15="Batal"),0,IF($Q15="",5,IF($Q15<0,50,IF($Q15<=Referensi!$P$5,40,IF($Q15<=Referensi!$P$6,30,IF($Q15<=Referensi!$P$7,20,10)))))+IF($O15="",25,IF($P15>Referensi!$P$8,30,IF($P15>Referensi!$P$9,20,5)))+IF($U15="",5,IF($U15>=Referensi!$P$10,20,IF($U15>=Referensi!$P$11,10,5)))+IF($L15="Tertunda",15,IF(OR($L15="Negosiasi",$L15="Penawaran"),12,IF($L15="Berjalan",8,IF($L15="Prospek",5,0)))))) -> 52 | T15: =IF($C15="","",IF(OR($L15="Selesai",$L15="Batal"),"Tidak aktif",IF($S15>=Referensi!$P$12,"KRITIS",IF($S15>=Referensi!$P$13,"Tinggi",IF($S15>=Referensi!$P$14,"Sedang","Rendah"))))) -> Sedang | U15: 140000000 | V15: Survei GPR | W15: =IF(OR($C15="",$T15="Tidak aktif"),"",$S15+ROW()/100000) -> 52.00015
A16: =IF($C16="","",ROW()-4) -> 12 | B16: {=IF(OR($C16="",$I16="",$J16=""),"","JSI-"&IFERROR(INDEX(Referensi!$B$5:$B$14,MATCH($I16,Referensi!$A$5:$A$14,0)),"???")&"-"&IFERROR(INDEX(Referensi!$E$5:$E$14,MATCH($J16,Referensi!$D$5:$D$14,0)),"???")&"-"&TEXT(COUNTIFS($I$5:$I16,$I16,$J$5:$J16,$J16),"000"))} -> JSI-ENT-JAS-010 | C16: Survei Stock Opname | D16: PT Carsurin | G16: Pomala | H16: Sulawesi Tenggara | I16: Enterprise JSI | J16: Jasa | K16: Nurdiyansah | L16: Negosiasi | P16: =IF(OR($C16="",$O16=""),"",TODAY()-$O16) | Q16: =IF(OR($C16="",$N16=""),"",$N16-TODAY()) | R16: =IF($C16="","",IF($O16="","Belum ada kontak",IF($P16>Referensi!$P$8,"Segera follow up",IF($P16>Referensi!$P$9,"Perlu dipantau","Terkini")))) -> Belum ada kontak | S16: =IF($C16="","",IF(OR($L16="Selesai",$L16="Batal"),0,IF($Q16="",5,IF($Q16<0,50,IF($Q16<=Referensi!$P$5,40,IF($Q16<=Referensi!$P$6,30,IF($Q16<=Referensi!$P$7,20,10)))))+IF($O16="",25,IF($P16>Referensi!$P$8,30,IF($P16>Referensi!$P$9,20,5)))+IF($U16="",5,IF($U16>=Referensi!$P$10,20,IF($U16>=Referensi!$P$11,10,5)))+IF($L16="Tertunda",15,IF(OR($L16="Negosiasi",$L16="Penawaran"),12,IF($L16="Berjalan",8,IF($L16="Prospek",5,0)))))) -> 47 | T16: =IF($C16="","",IF(OR($L16="Selesai",$L16="Batal"),"Tidak aktif",IF($S16>=Referensi!$P$12,"KRITIS",IF($S16>=Referensi!$P$13,"Tinggi",IF($S16>=Referensi!$P$14,"Sedang","Rendah"))))) -> Sedang | U16: 50000000 | V16: Survei Stock Opname | W16: =IF(OR($C16="",$T16="Tidak aktif"),"",$S16+ROW()/100000) -> 47.00016
A17: =IF($C17="","",ROW()-4) -> 13 | B17: {=IF(OR($C17="",$I17="",$J17=""),"","JSI-"&IFERROR(INDEX(Referensi!$B$5:$B$14,MATCH($I17,Referensi!$A$5:$A$14,0)),"???")&"-"&IFERROR(INDEX(Referensi!$E$5:$E$14,MATCH($J17,Referensi!$D$5:$D$14,0)),"???")&"-"&TEXT(COUNTIFS($I$5:$I17,$I17,$J$5:$J17,$J17),"000"))} -> JSI-ENT-JAS-011 | C17: Topografi LiDAR 1500 HA | D17: PT Anugerah Jaya Buana | E17: Masdar | G17: LuwuTimur | H17: Sulawesi Selatan | I17: Enterprise JSI | J17: Jasa | K17: Harir | L17: Negosiasi | P17: =IF(OR($C17="",$O17=""),"",TODAY()-$O17) | Q17: =IF(OR($C17="",$N17=""),"",$N17-TODAY()) | R17: =IF($C17="","",IF($O17="","Belum ada kontak",IF($P17>Referensi!$P$8,"Segera follow up",IF($P17>Referensi!$P$9,"Perlu dipantau","Terkini")))) -> Belum ada kontak | S17: =IF($C17="","",IF(OR($L17="Selesai",$L17="Batal"),0,IF($Q17="",5,IF($Q17<0,50,IF($Q17<=Referensi!$P$5,40,IF($Q17<=Referensi!$P$6,30,IF($Q17<=Referensi!$P$7,20,10)))))+IF($O17="",25,IF($P17>Referensi!$P$8,30,IF($P17>Referensi!$P$9,20,5)))+IF($U17="",5,IF($U17>=Referensi!$P$10,20,IF($U17>=Referensi!$P$11,10,5)))+IF($L17="Tertunda",15,IF(OR($L17="Negosiasi",$L17="Penawaran"),12,IF($L17="Berjalan",8,IF($L17="Prospek",5,0)))))) -> 52 | T17: =IF($C17="","",IF(OR($L17="Selesai",$L17="Batal"),"Tidak aktif",IF($S17>=Referensi!$P$12,"KRITIS",IF($S17>=Referensi!$P$13,"Tinggi",IF($S17>=Referensi!$P$14,"Sedang","Rendah"))))) -> Sedang | U17: 420523400 | V17: Topografi Lidar | W17: =IF(OR($C17="",$T17="Tidak aktif"),"",$S17+ROW()/100000) -> 52.00017
A18: =IF($C18="","",ROW()-4) -> 14 | B18: {=IF(OR($C18="",$I18="",$J18=""),"","JSI-"&IFERROR(INDEX(Referensi!$B$5:$B$14,MATCH($I18,Referensi!$A$5:$A$14,0)),"???")&"-"&IFERROR(INDEX(Referensi!$E$5:$E$14,MATCH($J18,Referensi!$D$5:$D$14,0)),"???")&"-"&TEXT(COUNTIFS($I$5:$I18,$I18,$J$5:$J18,$J18),"000"))} -> JSI-ENT-JAS-012 | C18: Topografi LiDAR 400HA | D18: PT Kungkilan Bukit Tengkiling | E18: Hakim | G18: Lahat | H18: Sumatera Selatan | I18: Enterprise JSI | J18: Jasa | K18: Rika | L18: Penawaran | P18: =IF(OR($C18="",$O18=""),"",TODAY()-$O18) | Q18: =IF(OR($C18="",$N18=""),"",$N18-TODAY()) | R18: =IF($C18="","",IF($O18="","Belum ada kontak",IF($P18>Referensi!$P$8,"Segera follow up",IF($P18>Referensi!$P$9,"Perlu dipantau","Terkini")))) -> Belum ada kontak | S18: =IF($C18="","",IF(OR($L18="Selesai",$L18="Batal"),0,IF($Q18="",5,IF($Q18<0,50,IF($Q18<=Referensi!$P$5,40,IF($Q18<=Referensi!$P$6,30,IF($Q18<=Referensi!$P$7,20,10)))))+IF($O18="",25,IF($P18>Referensi!$P$8,30,IF($P18>Referensi!$P$9,20,5)))+IF($U18="",5,IF($U18>=Referensi!$P$10,20,IF($U18>=Referensi!$P$11,10,5)))+IF($L18="Tertunda",15,IF(OR($L18="Negosiasi",$L18="Penawaran"),12,IF($L18="Berjalan",8,IF($L18="Prospek",5,0)))))) -> 52 | T18: =IF($C18="","",IF(OR($L18="Selesai",$L18="Batal"),"Tidak aktif",IF($S18>=Referensi!$P$12,"KRITIS",IF($S18>=Referensi!$P$13,"Tinggi",IF($S18>=Referensi!$P$14,"Sedang","Rendah"))))) -> Sedang | U18: 111888000 | V18: Topografi Lidar | W18: =IF(OR($C18="",$T18="Tidak aktif"),"",$S18+ROW()/100000) -> 52.00018
A19: =IF($C19="","",ROW()-4) -> 15 | B19: {=IF(OR($C19="",$I19="",$J19=""),"","JSI-"&IFERROR(INDEX(Referensi!$B$5:$B$14,MATCH($I19,Referensi!$A$5:$A$14,0)),"???")&"-"&IFERROR(INDEX(Referensi!$E$5:$E$14,MATCH($J19,Referensi!$D$5:$D$14,0)),"???")&"-"&TEXT(COUNTIFS($I$5:$I19,$I19,$J$5:$J19,$J19),"000"))} -> JSI-ENT-JAS-013 | C19: Topografi LIDAR 700HA | D19: Helen, Dasep Ahmadi | E19: Dasep Ahmadi | G19: Belitung | H19: Bangka Belitung | I19: Enterprise JSI | J19: Jasa | K19: Harir | L19: Penawaran | P19: =IF(OR($C19="",$O19=""),"",TODAY()-$O19) | Q19: =IF(OR($C19="",$N19=""),"",$N19-TODAY()) | R19: =IF($C19="","",IF($O19="","Belum ada kontak",IF($P19>Referensi!$P$8,"Segera follow up",IF($P19>Referensi!$P$9,"Perlu dipantau","Terkini")))) -> Belum ada kontak | S19: =IF($C19="","",IF(OR($L19="Selesai",$L19="Batal"),0,IF($Q19="",5,IF($Q19<0,50,IF($Q19<=Referensi!$P$5,40,IF($Q19<=Referensi!$P$6,30,IF($Q19<=Referensi!$P$7,20,10)))))+IF($O19="",25,IF($P19>Referensi!$P$8,30,IF($P19>Referensi!$P$9,20,5)))+IF($U19="",5,IF($U19>=Referensi!$P$10,20,IF($U19>=Referensi!$P$11,10,5)))+IF($L19="Tertunda",15,IF(OR($L19="Negosiasi",$L19="Penawaran"),12,IF($L19="Berjalan",8,IF($L19="Prospek",5,0)))))) -> 52 | T19: =IF($C19="","",IF(OR($L19="Selesai",$L19="Batal"),"Tidak aktif",IF($S19>=Referensi!$P$12,"KRITIS",IF($S19>=Referensi!$P$13,"Tinggi",IF($S19>=Referensi!$P$14,"Sedang","Rendah"))))) -> Sedang | U19: 165000000 | V19: Topografi Lidar | W19: =IF(OR($C19="",$T19="Tidak aktif"),"",$S19+ROW()/100000) -> 52.00019
A20: =IF($C20="","",ROW()-4) -> 16 | B20: {=IF(OR($C20="",$I20="",$J20=""),"","JSI-"&IFERROR(INDEX(Referensi!$B$5:$B$14,MATCH($I20,Referensi!$A$5:$A$14,0)),"???")&"-"&IFERROR(INDEX(Referensi!$E$5:$E$14,MATCH($J20,Referensi!$D$5:$D$14,0)),"???")&"-"&TEXT(COUNTIFS($I$5:$I20,$I20,$J$5:$J20,$J20),"000"))} -> JSI-ENT-PNJ-001 | C20: P60 CHCNAV, AA15 | D20: PT Bintang Delapan Mineral | E20: Angga | G20: Morowali | H20: Sulawesi Tengah | I20: Enterprise JSI | J20: Penjualan | K20: Rika | L20: Negosiasi | P20: =IF(OR($C20="",$O20=""),"",TODAY()-$O20) | Q20: =IF(OR($C20="",$N20=""),"",$N20-TODAY()) | R20: =IF($C20="","",IF($O20="","Belum ada kontak",IF($P20>Referensi!$P$8,"Segera follow up",IF($P20>Referensi!$P$9,"Perlu dipantau","Terkini")))) -> Belum ada kontak | S20: =IF($C20="","",IF(OR($L20="Selesai",$L20="Batal"),0,IF($Q20="",5,IF($Q20<0,50,IF($Q20<=Referensi!$P$5,40,IF($Q20<=Referensi!$P$6,30,IF($Q20<=Referensi!$P$7,20,10)))))+IF($O20="",25,IF($P20>Referensi!$P$8,30,IF($P20>Referensi!$P$9,20,5)))+IF($U20="",5,IF($U20>=Referensi!$P$10,20,IF($U20>=Referensi!$P$11,10,5)))+IF($L20="Tertunda",15,IF(OR($L20="Negosiasi",$L20="Penawaran"),12,IF($L20="Berjalan",8,IF($L20="Prospek",5,0)))))) -> 62 | T20: =IF($C20="","",IF(OR($L20="Selesai",$L20="Batal"),"Tidak aktif",IF($S20>=Referensi!$P$12,"KRITIS",IF($S20>=Referensi!$P$13,"Tinggi",IF($S20>=Referensi!$P$14,"Sedang","Rendah"))))) -> Tinggi | U20: 3600000000 | V20: Penjualan Unit Drone P60 dan AA15 | W20: =IF(OR($C20="",$T20="Tidak aktif"),"",$S20+ROW()/100000) -> 62.0002
A21: =IF($C21="","",ROW()-4) -> 17 | B21: {=IF(OR($C21="",$I21="",$J21=""),"","JSI-"&IFERROR(INDEX(Referensi!$B$5:$B$14,MATCH($I21,Referensi!$A$5:$A$14,0)),"???")&"-"&IFERROR(INDEX(Referensi!$E$5:$E$14,MATCH($J21,Referensi!$D$5:$D$14,0)),"???")&"-"&TEXT(COUNTIFS($I$5:$I21,$I21,$J$5:$J21,$J21),"000"))} -> JSI-ENT-PNJ-002 | C21: X500 CHCNAV, AA6 | D21: Dinas Perumahan Rakyat, Kab HST | E21: Aron | G21: Kab. Hulu Sungai Tengah | H21: Kalimantan Selatan | I21: Enterprise JSI | J21: Penjualan | K21: Rika | L21: Penawaran | P21: =IF(OR($C21="",$O21=""),"",TODAY()-$O21) | Q21: =IF(OR($C21="",$N21=""),"",$N21-TODAY()) | R21: =IF($C21="","",IF($O21="","Belum ada kontak",IF($P21>Referensi!$P$8,"Segera follow up",IF($P21>Referensi!$P$9,"Perlu dipantau","Terkini")))) -> Belum ada kontak | S21: =IF($C21="","",IF(OR($L21="Selesai",$L21="Batal"),0,IF($Q21="",5,IF($Q21<0,50,IF($Q21<=Referensi!$P$5,40,IF($Q21<=Referensi!$P$6,30,IF($Q21<=Referensi!$P$7,20,10)))))+IF($O21="",25,IF($P21>Referensi!$P$8,30,IF($P21>Referensi!$P$9,20,5)))+IF($U21="",5,IF($U21>=Referensi!$P$10,20,IF($U21>=Referensi!$P$11,10,5)))+IF($L21="Tertunda",15,IF(OR($L21="Negosiasi",$L21="Penawaran"),12,IF($L21="Berjalan",8,IF($L21="Prospek",5,0)))))) -> 62 | T21: =IF($C21="","",IF(OR($L21="Selesai",$L21="Batal"),"Tidak aktif",IF($S21>=Referensi!$P$12,"KRITIS",IF($S21>=Referensi!$P$13,"Tinggi",IF($S21>=Referensi!$P$14,"Sedang","Rendah"))))) -> Tinggi | U21: 585000000 | V21: Penjualan Unit DroneX500 dan AA6 | W21: =IF(OR($C21="",$T21="Tidak aktif"),"",$S21+ROW()/100000) -> 62.00021
A22: =IF($C22="","",ROW()-4) | B22: {=IF(OR($C22="",$I22="",$J22=""),"","JSI-"&IFERROR(INDEX(Referensi!$B$5:$B$14,MATCH($I22,Referensi!$A$5:$A$14,0)),"???")&"-"&IFERROR(INDEX(Referensi!$E$5:$E$14,MATCH($J22,Referensi!$D$5:$D$14,0)),"???")&"-"&TEXT(COUNTIFS($I$5:$I22,$I22,$J$5:$J22,$J22),"000"))} | P22: =IF(OR($C22="",$O22=""),"",TODAY()-$O22) | Q22: =IF(OR($C22="",$N22=""),"",$N22-TODAY()) | R22: =IF($C22="","",IF($O22="","Belum ada kontak",IF($P22>Referensi!$P$8,"Segera follow up",IF($P22>Referensi!$P$9,"Perlu dipantau","Terkini")))) | S22: =IF($C22="","",IF(OR($L22="Selesai",$L22="Batal"),0,IF($Q22="",5,IF($Q22<0,50,IF($Q22<=Referensi!$P$5,40,IF($Q22<=Referensi!$P$6,30,IF($Q22<=Referensi!$P$7,20,10)))))+IF($O22="",25,IF($P22>Referensi!$P$8,30,IF($P22>Referensi!$P$9,20,5)))+IF($U22="",5,IF($U22>=Referensi!$P$10,20,IF($U22>=Referensi!$P$11,10,5)))+IF($L22="Tertunda",15,IF(OR($L22="Negosiasi",$L22="Penawaran"),12,IF($L22="Berjalan",8,IF($L22="Prospek",5,0)))))) | T22: =IF($C22="","",IF(OR($L22="Selesai",$L22="Batal"),"Tidak aktif",IF($S22>=Referensi!$P$12,"KRITIS",IF($S22>=Referensi!$P$13,"Tinggi",IF($S22>=Referensi!$P$14,"Sedang","Rendah"))))) | W22: =IF(OR($C22="",$T22="Tidak aktif"),"",$S22+ROW()/100000)
A23: =IF($C23="","",ROW()-4) | B23: {=IF(OR($C23="",$I23="",$J23=""),"","JSI-"&IFERROR(INDEX(Referensi!$B$5:$B$14,MATCH($I23,Referensi!$A$5:$A$14,0)),"???")&"-"&IFERROR(INDEX(Referensi!$E$5:$E$14,MATCH($J23,Referensi!$D$5:$D$14,0)),"???")&"-"&TEXT(COUNTIFS($I$5:$I23,$I23,$J$5:$J23,$J23),"000"))} | P23: =IF(OR($C23="",$O23=""),"",TODAY()-$O23) | Q23: =IF(OR($C23="",$N23=""),"",$N23-TODAY()) | R23: =IF($C23="","",IF($O23="","Belum ada kontak",IF($P23>Referensi!$P$8,"Segera follow up",IF($P23>Referensi!$P$9,"Perlu dipantau","Terkini")))) | S23: =IF($C23="","",IF(OR($L23="Selesai",$L23="Batal"),0,IF($Q23="",5,IF($Q23<0,50,IF($Q23<=Referensi!$P$5,40,IF($Q23<=Referensi!$P$6,30,IF($Q23<=Referensi!$P$7,20,10)))))+IF($O23="",25,IF($P23>Referensi!$P$8,30,IF($P23>Referensi!$P$9,20,5)))+IF($U23="",5,IF($U23>=Referensi!$P$10,20,IF($U23>=Referensi!$P$11,10,5)))+IF($L23="Tertunda",15,IF(OR($L23="Negosiasi",$L23="Penawaran"),12,IF($L23="Berjalan",8,IF($L23="Prospek",5,0)))))) | T23: =IF($C23="","",IF(OR($L23="Selesai",$L23="Batal"),"Tidak aktif",IF($S23>=Referensi!$P$12,"KRITIS",IF($S23>=Referensi!$P$13,"Tinggi",IF($S23>=Referensi!$P$14,"Sedang","Rendah"))))) | W23: =IF(OR($C23="",$T23="Tidak aktif"),"",$S23+ROW()/100000)
A24: =IF($C24="","",ROW()-4) | B24: {=IF(OR($C24="",$I24="",$J24=""),"","JSI-"&IFERROR(INDEX(Referensi!$B$5:$B$14,MATCH($I24,Referensi!$A$5:$A$14,0)),"???")&"-"&IFERROR(INDEX(Referensi!$E$5:$E$14,MATCH($J24,Referensi!$D$5:$D$14,0)),"???")&"-"&TEXT(COUNTIFS($I$5:$I24,$I24,$J$5:$J24,$J24),"000"))} | P24: =IF(OR($C24="",$O24=""),"",TODAY()-$O24) | Q24: =IF(OR($C24="",$N24=""),"",$N24-TODAY()) | R24: =IF($C24="","",IF($O24="","Belum ada kontak",IF($P24>Referensi!$P$8,"Segera follow up",IF($P24>Referensi!$P$9,"Perlu dipantau","Terkini")))) | S24: =IF($C24="","",IF(OR($L24="Selesai",$L24="Batal"),0,IF($Q24="",5,IF($Q24<0,50,IF($Q24<=Referensi!$P$5,40,IF($Q24<=Referensi!$P$6,30,IF($Q24<=Referensi!$P$7,20,10)))))+IF($O24="",25,IF($P24>Referensi!$P$8,30,IF($P24>Referensi!$P$9,20,5)))+IF($U24="",5,IF($U24>=Referensi!$P$10,20,IF($U24>=Referensi!$P$11,10,5)))+IF($L24="Tertunda",15,IF(OR($L24="Negosiasi",$L24="Penawaran"),12,IF($L24="Berjalan",8,IF($L24="Prospek",5,0)))))) | T24: =IF($C24="","",IF(OR($L24="Selesai",$L24="Batal"),"Tidak aktif",IF($S24>=Referensi!$P$12,"KRITIS",IF($S24>=Referensi!$P$13,"Tinggi",IF($S24>=Referensi!$P$14,"Sedang","Rendah"))))) | W24: =IF(OR($C24="",$T24="Tidak aktif"),"",$S24+ROW()/100000)
A25: =IF($C25="","",ROW()-4) | B25: {=IF(OR($C25="",$I25="",$J25=""),"","JSI-"&IFERROR(INDEX(Referensi!$B$5:$B$14,MATCH($I25,Referensi!$A$5:$A$14,0)),"???")&"-"&IFERROR(INDEX(Referensi!$E$5:$E$14,MATCH($J25,Referensi!$D$5:$D$14,0)),"???")&"-"&TEXT(COUNTIFS($I$5:$I25,$I25,$J$5:$J25,$J25),"000"))} | P25: =IF(OR($C25="",$O25=""),"",TODAY()-$O25) | Q25: =IF(OR($C25="",$N25=""),"",$N25-TODAY()) | R25: =IF($C25="","",IF($O25="","Belum ada kontak",IF($P25>Referensi!$P$8,"Segera follow up",IF($P25>Referensi!$P$9,"Perlu dipantau","Terkini")))) | S25: =IF($C25="","",IF(OR($L25="Selesai",$L25="Batal"),0,IF($Q25="",5,IF($Q25<0,50,IF($Q25<=Referensi!$P$5,40,IF($Q25<=Referensi!$P$6,30,IF($Q25<=Referensi!$P$7,20,10)))))+IF($O25="",25,IF($P25>Referensi!$P$8,30,IF($P25>Referensi!$P$9,20,5)))+IF($U25="",5,IF($U25>=Referensi!$P$10,20,IF($U25>=Referensi!$P$11,10,5)))+IF($L25="Tertunda",15,IF(OR($L25="Negosiasi",$L25="Penawaran"),12,IF($L25="Berjalan",8,IF($L25="Prospek",5,0)))))) | T25: =IF($C25="","",IF(OR($L25="Selesai",$L25="Batal"),"Tidak aktif",IF($S25>=Referensi!$P$12,"KRITIS",IF($S25>=Referensi!$P$13,"Tinggi",IF($S25>=Referensi!$P$14,"Sedang","Rendah"))))) | W25: =IF(OR($C25="",$T25="Tidak aktif"),"",$S25+ROW()/100000)
A26: =IF($C26="","",ROW()-4) | B26: {=IF(OR($C26="",$I26="",$J26=""),"","JSI-"&IFERROR(INDEX(Referensi!$B$5:$B$14,MATCH($I26,Referensi!$A$5:$A$14,0)),"???")&"-"&IFERROR(INDEX(Referensi!$E$5:$E$14,MATCH($J26,Referensi!$D$5:$D$14,0)),"???")&"-"&TEXT(COUNTIFS($I$5:$I26,$I26,$J$5:$J26,$J26),"000"))} | P26: =IF(OR($C26="",$O26=""),"",TODAY()-$O26) | Q26: =IF(OR($C26="",$N26=""),"",$N26-TODAY()) | R26: =IF($C26="","",IF($O26="","Belum ada kontak",IF($P26>Referensi!$P$8,"Segera follow up",IF($P26>Referensi!$P$9,"Perlu dipantau","Terkini")))) | S26: =IF($C26="","",IF(OR($L26="Selesai",$L26="Batal"),0,IF($Q26="",5,IF($Q26<0,50,IF($Q26<=Referensi!$P$5,40,IF($Q26<=Referensi!$P$6,30,IF($Q26<=Referensi!$P$7,20,10)))))+IF($O26="",25,IF($P26>Referensi!$P$8,30,IF($P26>Referensi!$P$9,20,5)))+IF($U26="",5,IF($U26>=Referensi!$P$10,20,IF($U26>=Referensi!$P$11,10,5)))+IF($L26="Tertunda",15,IF(OR($L26="Negosiasi",$L26="Penawaran"),12,IF($L26="Berjalan",8,IF($L26="Prospek",5,0)))))) | T26: =IF($C26="","",IF(OR($L26="Selesai",$L26="Batal"),"Tidak aktif",IF($S26>=Referensi!$P$12,"KRITIS",IF($S26>=Referensi!$P$13,"Tinggi",IF($S26>=Referensi!$P$14,"Sedang","Rendah"))))) | W26: =IF(OR($C26="",$T26="Tidak aktif"),"",$S26+ROW()/100000)
A27: =IF($C27="","",ROW()-4) | B27: {=IF(OR($C27="",$I27="",$J27=""),"","JSI-"&IFERROR(INDEX(Referensi!$B$5:$B$14,MATCH($I27,Referensi!$A$5:$A$14,0)),"???")&"-"&IFERROR(INDEX(Referensi!$E$5:$E$14,MATCH($J27,Referensi!$D$5:$D$14,0)),"???")&"-"&TEXT(COUNTIFS($I$5:$I27,$I27,$J$5:$J27,$J27),"000"))} | P27: =IF(OR($C27="",$O27=""),"",TODAY()-$O27) | Q27: =IF(OR($C27="",$N27=""),"",$N27-TODAY()) | R27: =IF($C27="","",IF($O27="","Belum ada kontak",IF($P27>Referensi!$P$8,"Segera follow up",IF($P27>Referensi!$P$9,"Perlu dipantau","Terkini")))) | S27: =IF($C27="","",IF(OR($L27="Selesai",$L27="Batal"),0,IF($Q27="",5,IF($Q27<0,50,IF($Q27<=Referensi!$P$5,40,IF($Q27<=Referensi!$P$6,30,IF($Q27<=Referensi!$P$7,20,10)))))+IF($O27="",25,IF($P27>Referensi!$P$8,30,IF($P27>Referensi!$P$9,20,5)))+IF($U27="",5,IF($U27>=Referensi!$P$10,20,IF($U27>=Referensi!$P$11,10,5)))+IF($L27="Tertunda",15,IF(OR($L27="Negosiasi",$L27="Penawaran"),12,IF($L27="Berjalan",8,IF($L27="Prospek",5,0)))))) | T27: =IF($C27="","",IF(OR($L27="Selesai",$L27="Batal"),"Tidak aktif",IF($S27>=Referensi!$P$12,"KRITIS",IF($S27>=Referensi!$P$13,"Tinggi",IF($S27>=Referensi!$P$14,"Sedang","Rendah"))))) | W27: =IF(OR($C27="",$T27="Tidak aktif"),"",$S27+ROW()/100000)
A28: =IF($C28="","",ROW()-4) | B28: {=IF(OR($C28="",$I28="",$J28=""),"","JSI-"&IFERROR(INDEX(Referensi!$B$5:$B$14,MATCH($I28,Referensi!$A$5:$A$14,0)),"???")&"-"&IFERROR(INDEX(Referensi!$E$5:$E$14,MATCH($J28,Referensi!$D$5:$D$14,0)),"???")&"-"&TEXT(COUNTIFS($I$5:$I28,$I28,$J$5:$J28,$J28),"000"))} | P28: =IF(OR($C28="",$O28=""),"",TODAY()-$O28) | Q28: =IF(OR($C28="",$N28=""),"",$N28-TODAY()) | R28: =IF($C28="","",IF($O28="","Belum ada kontak",IF($P28>Referensi!$P$8,"Segera follow up",IF($P28>Referensi!$P$9,"Perlu dipantau","Terkini")))) | S28: =IF($C28="","",IF(OR($L28="Selesai",$L28="Batal"),0,IF($Q28="",5,IF($Q28<0,50,IF($Q28<=Referensi!$P$5,40,IF($Q28<=Referensi!$P$6,30,IF($Q28<=Referensi!$P$7,20,10)))))+IF($O28="",25,IF($P28>Referensi!$P$8,30,IF($P28>Referensi!$P$9,20,5)))+IF($U28="",5,IF($U28>=Referensi!$P$10,20,IF($U28>=Referensi!$P$11,10,5)))+IF($L28="Tertunda",15,IF(OR($L28="Negosiasi",$L28="Penawaran"),12,IF($L28="Berjalan",8,IF($L28="Prospek",5,0)))))) | T28: =IF($C28="","",IF(OR($L28="Selesai",$L28="Batal"),"Tidak aktif",IF($S28>=Referensi!$P$12,"KRITIS",IF($S28>=Referensi!$P$13,"Tinggi",IF($S28>=Referensi!$P$14,"Sedang","Rendah"))))) | W28: =IF(OR($C28="",$T28="Tidak aktif"),"",$S28+ROW()/100000)
A29: =IF($C29="","",ROW()-4) | B29: {=IF(OR($C29="",$I29="",$J29=""),"","JSI-"&IFERROR(INDEX(Referensi!$B$5:$B$14,MATCH($I29,Referensi!$A$5:$A$14,0)),"???")&"-"&IFERROR(INDEX(Referensi!$E$5:$E$14,MATCH($J29,Referensi!$D$5:$D$14,0)),"???")&"-"&TEXT(COUNTIFS($I$5:$I29,$I29,$J$5:$J29,$J29),"000"))} | P29: =IF(OR($C29="",$O29=""),"",TODAY()-$O29) | Q29: =IF(OR($C29="",$N29=""),"",$N29-TODAY()) | R29: =IF($C29="","",IF($O29="","Belum ada kontak",IF($P29>Referensi!$P$8,"Segera follow up",IF($P29>Referensi!$P$9,"Perlu dipantau","Terkini")))) | S29: =IF($C29="","",IF(OR($L29="Selesai",$L29="Batal"),0,IF($Q29="",5,IF($Q29<0,50,IF($Q29<=Referensi!$P$5,40,IF($Q29<=Referensi!$P$6,30,IF($Q29<=Referensi!$P$7,20,10)))))+IF($O29="",25,IF($P29>Referensi!$P$8,30,IF($P29>Referensi!$P$9,20,5)))+IF($U29="",5,IF($U29>=Referensi!$P$10,20,IF($U29>=Referensi!$P$11,10,5)))+IF($L29="Tertunda",15,IF(OR($L29="Negosiasi",$L29="Penawaran"),12,IF($L29="Berjalan",8,IF($L29="Prospek",5,0)))))) | T29: =IF($C29="","",IF(OR($L29="Selesai",$L29="Batal"),"Tidak aktif",IF($S29>=Referensi!$P$12,"KRITIS",IF($S29>=Referensi!$P$13,"Tinggi",IF($S29>=Referensi!$P$14,"Sedang","Rendah"))))) | W29: =IF(OR($C29="",$T29="Tidak aktif"),"",$S29+ROW()/100000)
A30: =IF($C30="","",ROW()-4) | B30: {=IF(OR($C30="",$I30="",$J30=""),"","JSI-"&IFERROR(INDEX(Referensi!$B$5:$B$14,MATCH($I30,Referensi!$A$5:$A$14,0)),"???")&"-"&IFERROR(INDEX(Referensi!$E$5:$E$14,MATCH($J30,Referensi!$D$5:$D$14,0)),"???")&"-"&TEXT(COUNTIFS($I$5:$I30,$I30,$J$5:$J30,$J30),"000"))} | P30: =IF(OR($C30="",$O30=""),"",TODAY()-$O30) | Q30: =IF(OR($C30="",$N30=""),"",$N30-TODAY()) | R30: =IF($C30="","",IF($O30="","Belum ada kontak",IF($P30>Referensi!$P$8,"Segera follow up",IF($P30>Referensi!$P$9,"Perlu dipantau","Terkini")))) | S30: =IF($C30="","",IF(OR($L30="Selesai",$L30="Batal"),0,IF($Q30="",5,IF($Q30<0,50,IF($Q30<=Referensi!$P$5,40,IF($Q30<=Referensi!$P$6,30,IF($Q30<=Referensi!$P$7,20,10)))))+IF($O30="",25,IF($P30>Referensi!$P$8,30,IF($P30>Referensi!$P$9,20,5)))+IF($U30="",5,IF($U30>=Referensi!$P$10,20,IF($U30>=Referensi!$P$11,10,5)))+IF($L30="Tertunda",15,IF(OR($L30="Negosiasi",$L30="Penawaran"),12,IF($L30="Berjalan",8,IF($L30="Prospek",5,0)))))) | T30: =IF($C30="","",IF(OR($L30="Selesai",$L30="Batal"),"Tidak aktif",IF($S30>=Referensi!$P$12,"KRITIS",IF($S30>=Referensi!$P$13,"Tinggi",IF($S30>=Referensi!$P$14,"Sedang","Rendah"))))) | W30: =IF(OR($C30="",$T30="Tidak aktif"),"",$S30+ROW()/100000)
A31: =IF($C31="","",ROW()-4) | B31: {=IF(OR($C31="",$I31="",$J31=""),"","JSI-"&IFERROR(INDEX(Referensi!$B$5:$B$14,MATCH($I31,Referensi!$A$5:$A$14,0)),"???")&"-"&IFERROR(INDEX(Referensi!$E$5:$E$14,MATCH($J31,Referensi!$D$5:$D$14,0)),"???")&"-"&TEXT(COUNTIFS($I$5:$I31,$I31,$J$5:$J31,$J31),"000"))} | P31: =IF(OR($C31="",$O31=""),"",TODAY()-$O31) | Q31: =IF(OR($C31="",$N31=""),"",$N31-TODAY()) | R31: =IF($C31="","",IF($O31="","Belum ada kontak",IF($P31>Referensi!$P$8,"Segera follow up",IF($P31>Referensi!$P$9,"Perlu dipantau","Terkini")))) | S31: =IF($C31="","",IF(OR($L31="Selesai",$L31="Batal"),0,IF($Q31="",5,IF($Q31<0,50,IF($Q31<=Referensi!$P$5,40,IF($Q31<=Referensi!$P$6,30,IF($Q31<=Referensi!$P$7,20,10)))))+IF($O31="",25,IF($P31>Referensi!$P$8,30,IF($P31>Referensi!$P$9,20,5)))+IF($U31="",5,IF($U31>=Referensi!$P$10,20,IF($U31>=Referensi!$P$11,10,5)))+IF($L31="Tertunda",15,IF(OR($L31="Negosiasi",$L31="Penawaran"),12,IF($L31="Berjalan",8,IF($L31="Prospek",5,0)))))) | T31: =IF($C31="","",IF(OR($L31="Selesai",$L31="Batal"),"Tidak aktif",IF($S31>=Referensi!$P$12,"KRITIS",IF($S31>=Referensi!$P$13,"Tinggi",IF($S31>=Referensi!$P$14,"Sedang","Rendah"))))) | W31: =IF(OR($C31="",$T31="Tidak aktif"),"",$S31+ROW()/100000)
A32: =IF($C32="","",ROW()-4) | B32: {=IF(OR($C32="",$I32="",$J32=""),"","JSI-"&IFERROR(INDEX(Referensi!$B$5:$B$14,MATCH($I32,Referensi!$A$5:$A$14,0)),"???")&"-"&IFERROR(INDEX(Referensi!$E$5:$E$14,MATCH($J32,Referensi!$D$5:$D$14,0)),"???")&"-"&TEXT(COUNTIFS($I$5:$I32,$I32,$J$5:$J32,$J32),"000"))} | P32: =IF(OR($C32="",$O32=""),"",TODAY()-$O32) | Q32: =IF(OR($C32="",$N32=""),"",$N32-TODAY()) | R32: =IF($C32="","",IF($O32="","Belum ada kontak",IF($P32>Referensi!$P$8,"Segera follow up",IF($P32>Referensi!$P$9,"Perlu dipantau","Terkini")))) | S32: =IF($C32="","",IF(OR($L32="Selesai",$L32="Batal"),0,IF($Q32="",5,IF($Q32<0,50,IF($Q32<=Referensi!$P$5,40,IF($Q32<=Referensi!$P$6,30,IF($Q32<=Referensi!$P$7,20,10)))))+IF($O32="",25,IF($P32>Referensi!$P$8,30,IF($P32>Referensi!$P$9,20,5)))+IF($U32="",5,IF($U32>=Referensi!$P$10,20,IF($U32>=Referensi!$P$11,10,5)))+IF($L32="Tertunda",15,IF(OR($L32="Negosiasi",$L32="Penawaran"),12,IF($L32="Berjalan",8,IF($L32="Prospek",5,0)))))) | T32: =IF($C32="","",IF(OR($L32="Selesai",$L32="Batal"),"Tidak aktif",IF($S32>=Referensi!$P$12,"KRITIS",IF($S32>=Referensi!$P$13,"Tinggi",IF($S32>=Referensi!$P$14,"Sedang","Rendah"))))) | W32: =IF(OR($C32="",$T32="Tidak aktif"),"",$S32+ROW()/100000)
